Workbook

Sheet AI Code
B1: AI Code Tool = Github Copilot - SLAI.Cline - Cursor - CodeGen - SLAI.Genie
B2: Data Source
A5: Feb. 26
C6: Leader | D6: Total | E6: AI Code Aoption | F6: AI Code Active | G6: Adoption Rate | H6: Active Rate
C7: Ang, Bense | D7: 99 | E7: 18 | F7: 13 | G7: =E7/D7 -> 0.18181818 | H7: =F7/D7 -> 0.13131313
C8: Chen, Fairy | D8: 80 | E8: 12 | F8: 14 | G8: =E8/D8 -> 0.15 | H8: =F8/D8 -> 0.175
C9: Fang, James | D9: 37 | E9: 13 | F9: 13 | G9: =E9/D9 -> 0.35135135 | H9: =F9/D9 -> 0.35135135
C10: Lu, Eagle | D10: 57 | E10: 9 | F10: 3 | G10: =E10/D10 -> 0.15789474 | H10: =F10/D10 -> 0.052631579
C11: Lu, Hansen | D11: 14 | E11: 1 | F11: 1 | G11: =E11/D11 -> 0.071428571 | H11: =F11/D11 -> 0.071428571
C12: Luo, Berlin | D12: 94 | E12: 44 | F12: 31 | G12: =E12/D12 -> 0.46808511 | H12: =F12/D12 -> 0.32978723
C13: Yan, Frank | D13: 83 | E13: 24 | F13: 21 | G13: =E13/D13 -> 0.28915663 | H13: =F13/D13 -> 0.25301205
C14: Zhang, Jia | D14: 18 | E14: 9 | F14: 8 | G14: =E14/D14 -> 0.5 | H14: =F14/D14 -> 0.44444444
C15: Zheng, Effie | D15: 96 | E15: 9 | F15: 9 | G15: =E15/D15 -> 0.09375 | H15: =F15/D15 -> 0.09375
C16: Li, Jessie | D16: 16 | E16: 14 | F16: 14 | G16: =E16/D16 -> 0.875 | H16: =F16/D16 -> 0.875
C17: Zheng, Ivan | D17: 23 | E17: 12 | F17: 12 | G17: =E17/D17 -> 0.52173913 | H17: =F17/D17 -> 0.52173913
C18: Total | D18: =SUM(D7:D17) -> 617 | E18: =SUM(E7:E17) -> 165 | F18: =SUM(F7:F17) -> 139 | G18: =E18/D18 -> 0.26742301 | H18: =F18/D18 -> 0.22528363
B20: Function | C20: Leader | D20: Total | E20: AI Code Aoption | F20: AI Code Active | G20: Adoption Rate | H20: Active Rate
B21: Validation | C21: Ang, Bense | D21: =SUM(D7,D10,D12) -> 250 | E21: =SUM(E7,E10,E12) -> 71 | F21: =SUM(F7,F10,F12) -> 47 | G21: =E21/D21 -> 0.284 | H21: =F21/D21 -> 0.188
B22: Platform Design | C22: Chen, Fairy | D22: 80 | E22: =E8 -> 12 | F22: =F8 -> 14 | G22: =E22/D22 -> 0.15 | H22: =F22/D22 -> 0.175
B23: Program Leadership | C23: Lu, Hansen | D23: 14 | E23: =E11 -> 1 | F23: =F11 -> 1 | G23: =E23/D23 -> 0.071428571 | H23: =F23/D23 -> 0.071428571
B24: Debug | C24: Yan, Frank | D24: 83 | E24: =E13 -> 24 | F24: =F13 -> 21 | G24: =E24/D24 -> 0.28915663 | H24: =F24/D24 -> 0.25301205
B25: PPO | C25: Zhang, Jia | D25: =SUM(D14,D9) -> 55 | E25: =SUM(E14,E9) -> 22 | F25: =SUM(F14,F9) -> 21 | G25: =E25/D25 -> 0.4 | H25: =F25/D25 -> 0.38181818
B26: Sustaining | C26: Zheng, Effie | D26: 96 | E26: =F15 -> 9 | F26: =F15 -> 9 | G26: =E26/D26 -> 0.09375 | H26: =F26/D26 -> 0.09375
B27: FW Dev | C27: Jessie/Ivan | D27: =SUM(D16:D17) -> 39 | E27: =SUM(E16:E17) -> 26 | F27: =SUM(F16:F17) -> 26 | G27: =E27/D27 -> 0.66666667 | H27: =F27/D27 -> 0.66666667
C28: Total | D28: =SUM(D21:D27) -> 617 | E28: =SUM(E21:E27) -> 165 | F28: =SUM(F21:F27) -> 139 | G28: =E28/D28 -> 0.26742301 | H28: =F28/D28 -> 0.22528363
A30: Jan. 26
C31: Leader | D31: Total | E31: AI Code Aoption | F31: AI Code Active | G31: Adoption Rate | H31: Active Rate
C32: Ang, Bense | D32: 99 | E32: 13 | F32: 13 | G32: =E32/D32 -> 0.13131313 | H32: =F32/D32 -> 0.13131313
C33: Chen, Fairy | D33: 80 | E33: 8 | F33: 8 | G33: =E33/D33 -> 0.1 | H33: =F33/D33 -> 0.1
C34: Fang, James | D34: 37 | E34: 13 | F34: 13 | G34: =E34/D34 -> 0.35135135 | H34: =F34/D34 -> 0.35135135
C35: Lu, Eagle | D35: 57 | E35: 3 | F35: 3 | G35: =E35/D35 -> 0.052631579 | H35: =F35/D35 -> 0.052631579
C36: Lu, Hansen | D36: 14 | E36: 1 | F36: 1 | G36: =E36/D36 -> 0.071428571 | H36: =F36/D36 -> 0.071428571
C37: Luo, Berlin | D37: 94 | E37: 31 | F37: 31 | G37: =E37/D37 -> 0.32978723 | H37: =F37/D37 -> 0.32978723
C38: Yan, Frank | D38: 83 | E38: 21 | F38: 21 | G38: =E38/D38 -> 0.25301205 | H38: =F38/D38 -> 0.25301205
C39: Zhang, Jia | D39: 18 | E39: 8 | F39: 8 | G39: =E39/D39 -> 0.44444444 | H39: =F39/D39 -> 0.44444444
C40: Zheng, Effie | D40: 96 | E40: 9 | F40: 9 | G40: =E40/D40 -> 0.09375 | H40: =F40/D40 -> 0.09375
C41: Li, Jessie | D41: 16 | E41: 14 | F41: 14 | G41: =E41/D41 -> 0.875 | H41: =F41/D41 -> 0.875
C42: Zheng, Ivan | D42: 23 | E42: 12 | F42: 12 | G42: =E42/D42 -> 0.52173913 | H42: =F42/D42 -> 0.52173913
C43: Total | D43: =SUM(D32:D42) -> 617 | E43: =SUM(E32:E42) -> 133 | F43: =SUM(F32:F42) -> 133 | G43: =E43/D43 -> 0.21555916 | H43: =F43/D43 -> 0.21555916
B45: Function | C45: Leader | D45: Total | E45: AI Code Aoption | F45: AI Code Active | G45: Adoption Rate | H45: Active Rate
...

Sheet NABU
B1: active = used NABU in last 7 days
B2: Source
A5: Feb. 26
C6: Leader | D6: Total | E6: NABU adoption | F6: NABU active | G6: Adoption Rate | H6: Active Rate
C7: Ang, Bense | D7: 99 | E7: 70 | F7: 24 | G7: =E7/D7 -> 0.70707071 | H7: =F7/D7 -> 0.24242424
C8: Chen, Fairy | D8: 80 | E8: 63 | F8: 51 | G8: =E8/D8 -> 0.7875 | H8: =F8/D8 -> 0.6375
C9: Fang, James | D9: 37 | E9: 30 | F9: 25 | G9: =E9/D9 -> 0.81081081 | H9: =F9/D9 -> 0.67567568
C10: Lu, Eagle | D10: 57 | E10: 38 | F10: 21 | G10: =E10/D10 -> 0.66666667 | H10: =F10/D10 -> 0.36842105
C11: Lu, Hansen | D11: 14 | E11: 10 | F11: 3 | G11: =E11/D11 -> 0.71428571 | H11: =F11/D11 -> 0.21428571
C12: Luo, Berlin | D12: 94 | E12: 82 | F12: 50 | G12: =E12/D12 -> 0.87234043 | H12: =F12/D12 -> 0.53191489
C13: Yan, Frank | D13: 83 | E13: 66 | F13: 44 | G13: =E13/D13 -> 0.79518072 | H13: =F13/D13 -> 0.53012048
C14: Zhang, Jia | D14: 18 | E14: 19 | F14: 18 | G14: =E14/D14 -> 1.0555556 | H14: =F14/D14 -> 1
C15: Zheng, Effie | D15: 96 | E15: 50 | F15: 31 | G15: =E15/D15 -> 0.52083333 | H15: =F15/D15 -> 0.32291667
C16: Li, Jessie | D16: 16 | E16: 16 | F16: 13 | G16: =E16/D16 -> 1 | H16: =F16/D16 -> 0.8125
C17: Zheng, Ivan | D17: 23 | E17: 12 | F17: 7 | G17: =E17/D17 -> 0.52173913 | H17: =F17/D17 -> 0.30434783
C18: Total | D18: =SUM(D7:D17) -> 617 | E18: =SUM(E7:E17) -> 456 | F18: =SUM(F7:F17) -> 287 | G18: =E18/D18 -> 0.73905997 | H18: =F18/D18 -> 0.46515397
B20: Function | C20: Leader | D20: Total | E20: NABU adoption | F20: NABU active | G20: Adoption Rate | H20: Active Rate
B21: Validation | C21: Ang, Bense | D21: =SUM(D7,D10,D12) -> 250 | E21: =SUM(E7,E10,E12) -> 190 | F21: =SUM(F7,F10,F12) -> 95 | G21: =E21/D21 -> 0.76 | H21: =F21/D21 -> 0.38
B22: Platform Design | C22: Chen, Fairy | D22: 80 | E22: =E8 -> 63 | F22: =F8 -> 51 | G22: =E22/D22 -> 0.7875 | H22: =F22/D22 -> 0.6375
B23: Program Leadership | C23: Lu, Hansen | D23: 14 | E23: =E11 -> 10 | F23: =F11 -> 3 | G23: =E23/D23 -> 0.71428571 | H23: =F23/D23 -> 0.21428571
B24: Debug | C24: Yan, Frank | D24: 83 | E24: =E13 -> 66 | F24: =F13 -> 44 | G24: =E24/D24 -> 0.79518072 | H24: =F24/D24 -> 0.53012048
B25: PPO | C25: Zhang, Jia | D25: =SUM(D14,D9) -> 55 | E25: =SUM(E14,E9) -> 49 | F25: =SUM(F14,F9) -> 43 | G25: =E25/D25 -> 0.89090909 | H25: =F25/D25 -> 0.78181818
B26: Sustaining | C26: Zheng, Effie | D26: 96 | E26: =E15 -> 50 | F26: =F15 -> 31 | G26: =E26/D26 -> 0.52083333 | H26: =F26/D26 -> 0.32291667
B27: FW Dev | C27: Jessie/Ivan | D27: =SUM(D16:D17) -> 39 | E27: =SUM(E16:E17) -> 28 | F27: =SUM(F16:F17) -> 20 | G27: =E27/D27 -> 0.71794872 | H27: =F27/D27 -> 0.51282051
C28: Total | D28: =SUM(D21:D27) -> 617 | E28: =SUM(E21:E27) -> 456 | F28: =SUM(F21:F27) -> 287 | G28: =E28/D28 -> 0.73905997 | H28: =F28/D28 -> 0.46515397
A30: Jan. 26
C31: Leader | D31: Total | E31: NABU adoption | F31: NABU active | G31: Adoption Rate | H31: Active Rate
C32: Ang, Bense | D32: 99 | E32: 63 | F32: 24 | G32: =E32/D32 -> 0.63636364 | H32: =F32/D32 -> 0.24242424
C33: Chen, Fairy | D33: 80 | E33: 58 | F33: 22 | G33: =E33/D33 -> 0.725 | H33: =F33/D33 -> 0.275
C34: Fang, James | D34: 37 | E34: 29 | F34: 11 | G34: =E34/D34 -> 0.78378378 | H34: =F34/D34 -> 0.2972973
C35: Lu, Eagle | D35: 57 | E35: 37 | F35: 13 | G35: =E35/D35 -> 0.64912281 | H35: =F35/D35 -> 0.22807018
C36: Lu, Hansen | D36: 14 | E36: 9 | F36: 1 | G36: =E36/D36 -> 0.64285714 | H36: =F36/D36 -> 0.071428571
C37: Luo, Berlin | D37: 94 | E37: 77 | F37: 22 | G37: =E37/D37 -> 0.81914894 | H37: =F37/D37 -> 0.23404255
C38: Yan, Frank | D38: 83 | E38: 63 | F38: 27 | G38: =E38/D38 -> 0.75903614 | H38: =F38/D38 -> 0.3253012
C39: Zhang, Jia | D39: 18 | E39: 18 | F39: 10 | G39: =E39/D39 -> 1 | H39: =F39/D39 -> 0.55555556
C40: Zheng, Effie | D40: 96 | E40: 44 | F40: 16 | G40: =E40/D40 -> 0.45833333 | H40: =F40/D40 -> 0.16666667
C41: Li, Jessie | D41: 16 | E41: 14 | F41: 7 | G41: =E41/D41 -> 0.875 | H41: =F41/D41 -> 0.4375
C42: Zheng, Ivan | D42: 23 | E42: 12 | F42: 2 | G42: =E42/D42 -> 0.52173913 | H42: =F42/D42 -> 0.086956522
C43: Total | D43: =SUM(D32:D42) -> 617 | E43: =SUM(E32:E42) -> 424 | F43: =SUM(F32:F42) -> 155 | G43: =E43/D43 -> 0.68719611 | H43: =F43/D43 -> 0.25121556
B45: Function | C45: Leader | D45: Total | E45: NABU adoption | F45: NABU active | G45: Adoption Rate | H45: Active Rate
...

Sheet Microsoft Copilot
B1: active = At least one use in one week
B2: action = Teams meeting recap, meeting summarize,email coach, email draft, power point chat, word draft/re-write
B3: Source
A5: Feb. 26
B6: Organization | C6: Function | D6: Leader | E6: Active Copilot users | F6: Average weekly actions performed | G6: Copilot licensed users | H6: Total actions performed
B7: CE Eng Leadership | E7: 10 | F7: 36 | G7: 14 | H7: 10366
B8: CGCE Architecture | E8: 6 | F8: 19 | G8: 10 | H8: 4342 | J8: Validation | K8: Client Sys Val
B9: CGE Operations | E9: 5 | F9: 16 | G9: 5 | H9: 3501 | J9: Validation | K9: GPU Sys Val
B10: CLIENT PM - MOBILE | E10: 4 | F10: 19 | G10: 5 | H10: 3639 | J10: Validation | K10: IO Validation
B11: CLIENT PWR MEM - US | E11: 5 | F11: 21 | G11: 7 | H11: 3207 | J11: Validation | K11: Memory
B12: Client Sys Val | C12: Validation | D12: Ang, Bense | E12: 17 | F12: 28 | G12: 19 | H12: 8229 | J12: Platform Design | K12: PCBCAD/COMP
B13: Client ULP PPO TW | E13: 2 | F13: 8 | G13: 5 | H13: 911 | J13: Platform Design | K13: Platform Design
B14: CUSTOMER ENGINEERING | E14: 13 | F14: 18 | G14: 16 | H14: 8198 | J14: Platform Design | K14: Platform Design PM
B15: GFX Feature | C15: Debug | D15: Yan, Frank | E15: 7 | F15: 12 | G15: 8 | H15: 2275 | J15: Platform Design | K15: ThermMech
B16: GPU Sys Val | C16: Validation | D16: Ang, Bense | E16: 8 | F16: 16 | G16: 8 | H16: 1891 | J16: Program Leadership | K16: Program Leadership
B17: IO Validation | C17: Validation | D17: Ang, Bense | E17: 6 | F17: 25 | G17: 6 | H17: 4074 | J17: Debug | K17: GFX Feature
B18: LSE - Mobile US | E18: 7 | F18: 22 | G18: 8 | H18: 4851 | J18: Debug | K18: PLATFORM FEATURE VAL
B19: Memory | C19: Validation | D19: Ang, Bense | E19: 14 | F19: 15 | G19: 21 | H19: 3638 | J19: Debug | K19: Sys Enablement&Dev
B20: PCBCAD/COMP | C20: Platform Design | D20: Chen, Fairy | E20: 9 | F20: 41 | G20: 9 | H20: 3799 | J20: PPO | K20: Power&Performance
B21: Platform Design | C21: Platform Design | D21: Chen, Fairy | E21: 27 | F21: 38 | G21: 35 | H21: 12955 | J21: PPO | K21: PPA&SPPE
B22: Platform Design PM | C22: Platform Design | D22: Chen, Fairy | E22: 6 | F22: 33 | G22: 6 | H22: 2933 | J22: Sustaining | K22: Sustaining Val&Ops
B23: PLATFORM FEATURE VAL | C23: Debug | D23: Yan, Frank | E23: 29 | F23: 17 | G23: 34 | H23: 7452 | J23: FW Dev | K23: SHA AGESA/BV&Tools
B24: Power&Performance | C24: PPO | D24: Zhang, Jia | E24: 5 | F24: 28 | G24: 6 | H24: 1866 | J24: FW Dev | K24: Shanghai SBIOS
B25: PPA&SPPE | C25: PPO | D25: Zhang, Jia | E25: 5 | F25: 15 | G25: 7 | H25: 2523
B26: Program leadership | C26: Program Leadership | D26: Lu, Hansen | E26: 13 | F26: 29 | G26: 13 | H26: 16128
B27: SHA AGESA/BV&Tools | C27: FW Dev | D27: Jessie/Ivan | E27: 6 | F27: 21 | G27: 7 | H27: 1996
B28: Shanghai SBIOS | C28: FW Dev | D28: Jessie/Ivan | E28: 12 | F28: 20 | G28: 14 | H28: 6048
B29: Sustaining Val&Ops | C29: Sustaining | D29: Zheng, Effie | E29: 14 | F29: 15 | G29: 15 | H29: 1893
B30: Sys Enablement&Dev | C30: Debug | D30: Yan, Frank | E30: 31 | F30: 37 | G30: 34 | H30: 21373
B31: System Solution - US | E31: 4 | F31: 16 | G31: 5 | H31: 2559
B32: Taipei SBIOS | E32: 5 | F32: 12 | G32: 8 | H32: 3586
B33: TEG Alliance - US | E33: 6 | F33: 13 | G33: 8 | H33: 3037
B34: ThermMech | C34: Platform Design | D34: Chen, Fairy | E34: 8 | F34: 29 | G34: 8 | H34: 5267
B36: Function | C36: Leader | D36: Total | E36: Active Copilot users | F36: Average weekly actions performed | G36: Copilot licensed users | H36: Total actions performed | I36: Adoption Rate | J36: Active Rate | K36: Avg. Action Per User
B37: Validation | C37: Ang, Bense | D37: 250 | E37: {=SUMPRODUCT( E$7:E$34, --ISNUMBER( MATCH( $B$7:$B$34, IF($J$8:$J$24=$B37, $K$8:$K$24), 0 ) ) )} -> 45 | F37: {=SUMPRODUCT( F$7:F$34, --ISNUMBER( MATCH( $B$7:$B$34, IF($J$8:$J$24=$B37, $K$8:$K$24), 0 ) ) )} -> 84 | G37: {=SUMPRODUCT( G$7:G$34, --ISNUMBER( MATCH( $B$7:$B$34, IF($J$8:$J$24=$B37, $K$8:$K$24), 0 ) ) )} -> 54 | H37: {=SUMPRODUCT( H$7:H$34, --ISNUMBER( MATCH( $B$7:$B$34, IF($J$8:$J$24=$B37, $K$8:$K$24), 0 ) ) )} -> 17832 | I37: =G37/D37 -> 0.216 | J37: =E37/D37 -> 0.18 | K37: =H37/G37 -> 330.22222
B38: Platform Design | C38: Chen, Fairy | D38: 80 | E38: {=SUMPRODUCT( E$7:E$34, --ISNUMBER( MATCH( $B$7:$B$34, IF($J$8:$J$24=$B38, $K$8:$K$24), 0 ) ) )} -> 50 | F38: {=SUMPRODUCT( F$7:F$34, --ISNUMBER( MATCH( $B$7:$B$34, IF($J$8:$J$24=$B38, $K$8:$K$24), 0 ) ) )} -> 141 | G38: {=SUMPRODUCT( G$7:G$34, --ISNUMBER( MATCH( $B$7:$B$34, IF($J$8:$J$24=$B38, $K$8:$K$24), 0 ) ) )} -> 58 | H38: {=SUMPRODUCT( H$7:H$34, --ISNUMBER( MATCH( $B$7:$B$34, IF($J$8:$J$24=$B38, $K$8:$K$24), 0 ) ) )} -> 24954 | I38: =G38/D38 -> 0.725 | J38: =E38/D38 -> 0.625 | K38: =H38/G38 -> 430.24138
B39: Program Leadership | C39: Lu, Hansen | D39: 14 | E39: {=SUMPRODUCT( E$7:E$34, --ISNUMBER( MATCH( $B$7:$B$34, IF($J$8:$J$24=$B39, $K$8:$K$24), 0 ) ) )} -> 13 | F39: {=SUMPRODUCT( F$7:F$34, --ISNUMBER( MATCH( $B$7:$B$34, IF($J$8:$J$24=$B39, $K$8:$K$24), 0 ) ) )} -> 29 | G39: {=SUMPRODUCT( G$7:G$34, --ISNUMBER( MATCH( $B$7:$B$34, IF($J$8:$J$24=$B39, $K$8:$K$24), 0 ) ) )} -> 13 | H39: {=SUMPRODUCT( H$7:H$34, --ISNUMBER( MATCH( $B$7:$B$34, IF($J$8:$J$24=$B39, $K$8:$K$24), 0 ) ) )} -> 16128 | I39: =G39/D39 -> 0.92857143 | J39: =E39/D39 -> 0.92857143 | K39: =H39/G39 -> 1240.6154
B40: Debug | C40: Yan, Frank | D40: 83 | E40: {=SUMPRODUCT( E$7:E$34, --ISNUMBER( MATCH( $B$7:$B$34, IF($J$8:$J$24=$B40, $K$8:$K$24), 0 ) ) )} -> 67 | F40: {=SUMPRODUCT( F$7:F$34, --ISNUMBER( MATCH( $B$7:$B$34, IF($J$8:$J$24=$B40, $K$8:$K$24), 0 ) ) )} -> 66 | G40: {=SUMPRODUCT( G$7:G$34, --ISNUMBER( MATCH( $B$7:$B$34, IF($J$8:$J$24=$B40, $K$8:$K$24), 0 ) ) )} -> 76 | H40: {=SUMPRODUCT( H$7:H$34, --ISNUMBER( MATCH( $B$7:$B$34, IF($J$8:$J$24=$B40, $K$8:$K$24), 0 ) ) )} -> 31100 | I40: =G40/D40 -> 0.91566265 | J40: =E40/D40 -> 0.80722892 | K40: =H40/G40 -> 409.21053
B41: PPO | C41: Zhang, Jia | D41: 55 | E41: {=SUMPRODUCT( E$7:E$34, --ISNUMBER( MATCH( $B$7:$B$34, IF($J$8:$J$24=$B41, $K$8:$K$24), 0 ) ) )} -> 10 | F41: {=SUMPRODUCT( F$7:F$34, --ISNUMBER( MATCH( $B$7:$B$34, IF($J$8:$J$24=$B41, $K$8:$K$24), 0 ) ) )} -> 43 | G41: {=SUMPRODUCT( G$7:G$34, --ISNUMBER( MATCH( $B$7:$B$34, IF($J$8:$J$24=$B41, $K$8:$K$24), 0 ) ) )} -> 13 | H41: {=SUMPRODUCT( H$7:H$34, --ISNUMBER( MATCH( $B$7:$B$34, IF($J$8:$J$24=$B41, $K$8:$K$24), 0 ) ) )} -> 4389 | I41: =G41/D41 -> 0.23636364 | J41: =E41/D41 -> 0.18181818 | K41: =H41/G41 -> 337.61538
B42: Sustaining | C42: Zheng, Effie | D42: 96 | E42: {=SUMPRODUCT( E$7:E$34, --ISNUMBER( MATCH( $B$7:$B$34, IF($J$8:$J$24=$B42, $K$8:$K$24), 0 ) ) )} -> 14 | F42: {=SUMPRODUCT( F$7:F$34, --ISNUMBER( MATCH( $B$7:$B$34, IF($J$8:$J$24=$B42, $K$8:$K$24), 0 ) ) )} -> 15 | G42: {=SUMPRODUCT( G$7:G$34, --ISNUMBER( MATCH( $B$7:$B$34, IF($J$8:$J$24=$B42, $K$8:$K$24), 0 ) ) )} -> 15 | H42: {=SUMPRODUCT( H$7:H$34, --ISNUMBER( MATCH( $B$7:$B$34, IF($J$8:$J$24=$B42, $K$8:$K$24), 0 ) ) )} -> 1893 | I42: =G42/D42 -> 0.15625 | J42: =E42/D42 -> 0.14583333 | K42: =H42/G42 -> 126.2
...

Sheet Diagram
A3: Row Labels | B3: Sum of Total | C3: Sum of Copilot licensed users | D3: Sum of Active Copilot users | E3: Sum of Adoption Rate | F3: Sum of Active Rate | G3: Sum of Total actions performed | H3: Sum of Avg. Action Per User
A4: Debug | B4: 83 | C4: 46 | D4: 38 | E4: 0.55421687 | F4: 0.45783133 | G4: 10640 | H4: 280
A5: FW Dev | B5: 39 | C5: 18 | D5: 14 | E5: 0.46153846 | F5: 0.35897436 | G5: 4090 | H5: 292.14286
A6: Platform Design | B6: 80 | C6: 10 | D6: 4 | E6: 0.125 | F6: 0.05 | G6: 2746 | H6: 686.5
A7: PPO | B7: 55 | C7: 5 | D7: 3 | E7: 0.090909091 | F7: 0.054545455 | G7: 944 | H7: 314.66667
A8: Program Leadership | B8: 14 | C8: 13 | D8: 12 | E8: 0.92857143 | F8: 0.85714286 | G8: 11282 | H8: 940.16667
A9: Sustaining | B9: 96 | C9: 6 | D9: 6 | E9: 0.0625 | F9: 0.0625 | G9: 748 | H9: 124.66667
A10: Validation | B10: 250 | C10: 19 | D10: 13 | E10: 0.076 | F10: 0.052 | G10: 3866 | H10: 297.38462
A11: (blank) | B11: 617 | C11: 117 | D11: 90 | E11: 0.18962723 | F11: 0.1458671 | G11: 34316 | H11: 381.28889
A12: Grand Total | B12: 1234 | C12: 234 | D12: 180 | E12: 2.4883631 | F12: 2.0388611 | G12: 68632 | H12: 3316.8164
B21: NABU Adoption | C21: NABU Aactive
A22: =NABU!A5 -> Feb. 26 | B22: =NABU!G28 -> 0.73905997 | C22: =NABU!H28 -> 0.46515397
A23: =NABU!A30 -> Jan. 26 | B23: =NABU!G53 -> 0.68719611 | C23: =NABU!H53 -> 0.25121556
B25: AI Code Adoption

Sheet Sheet4
A1: Organization | B1: Function | C1: Leader | D1: Active Copilot users | E1: Average weekly actions performed | F1: Copilot licensed users | G1: Total actions performed
A2: Sustaining Val&Ops | B2: Sustaining | C2: Zheng, Effie | D2: 6 | E2: 7 | F2: 6 | G2: 748
A3: TEG Alliance - US | D3: 3 | E3: 17 | F3: 5 | G3: 2102
A4: Tech Docs - US | D4: 5 | E4: 21 | F4: 5 | G4: 4283
A5: Taipei SBIOS | D5: 5 | E5: 9 | F5: 8 | G5: 2754
A6: sys enablement&dev | B6: Debug | C6: Yan, Frank | D6: 18 | E6: 27 | F6: 21 | G6: 6596
A7: Shanghai SBIOS | B7: FW Dev | C7: Jessie/Ivan | D7: 11 | E7: 19 | F7: 12 | G7: 3146
A8: SHA AGESA/BV&Tools | B8: FW Dev | C8: Jessie/Ivan | D8: 3 | E8: 12 | F8: 6 | G8: 944
A9: Program leadership | B9: Program Leadership | C9: Lu, Hansen | D9: 12 | E9: 22 | F9: 13 | G9: 11282
A10: PPA&SPPE | B10: PPO | C10: Zhang, Jia | D10: 3 | E10: 9 | F10: 5 | G10: 1254
A11: Platform Feature Val | B11: Debug | C11: Yan, Frank | D11: 15 | E11: 18 | F11: 19 | G11: 2539
A12: Platform Design | B12: Platform Design | C12: Chen, Fairy | D12: 4 | E12: 18 | F12: 10 | G12: 2746
A13: Memory | B13: Validation | C13: Ang, Bense | D13: 7 | E13: 11 | F13: 9 | G13: 1081
A14: LSE - Mobile US | D14: 7 | E14: 22 | F14: 8 | G14: 3372
A15: GFX Feature | B15: Debug | C15: Yan, Frank | D15: 5 | E15: 12 | F15: 6 | G15: 1505
A16: Customer Engineering | D16: 9 | E16: 17 | F16: 10 | G16: 5813
A17: Client ULP PPO TW | D17: 2 | E17: 8 | F17: 5 | G17: 578
A18: client sys val | B18: Validation | C18: Ang, Bense | D18: 6 | E18: 30 | F18: 10 | G18: 2785
A19: Client Pwr Mem - US | D19: 2 | E19: 14 | F19: 6 | G19: 1938
A20: CLIENT PM - MOBILE | D20: 3 | E20: 17 | F20: 5 | G20: 2532
A21: CGE Operations | D21: 5 | E21: 12 | F21: 5 | G21: 2540
A22: CGCE Architecture | D22: 4 | E22: 15 | F22: 7 | G22: 2665
A23: CE Eng Leadership | D23: 7 | E23: 19 | F23: 12 | G23: 4692
A26: Organization | B26: Function | C26: Leader | D26: Active Copilot users | E26: Average weekly actions performed | F26: Copilot licensed users | G26: Total actions performed
A27: CE Eng Leadership | D27: 10 | E27: 36 | F27: 14 | G27: 10366
A28: CGCE Architecture | D28: 6 | E28: 19 | F28: 10 | G28: 4342
A29: CGE Operations | D29: 5 | E29: 16 | F29: 5 | G29: 3501
A30: CLIENT PM - MOBILE | D30: 4 | E30: 19 | F30: 5 | G30: 3639
A31: CLIENT PWR MEM - US | D31: 5 | E31: 21 | F31: 7 | G31: 3207
A32: Client Sys Val | B32: Validation | C32: Ang, Bense | D32: 17 | E32: 28 | F32: 19 | G32: 8229
A33: Client ULP PPO TW | D33: 2 | E33: 8 | F33: 5 | G33: 911
A34: CUSTOMER ENGINEERING | D34: 13 | E34: 18 | F34: 16 | G34: 8198
A35: GFX Feature | B35: Debug | C35: Yan, Frank | D35: 7 | E35: 12 | F35: 8 | G35: 2275
A36: GPU Sys Val | B36: Validation | C36: Ang, Bense | D36: 8 | E36: 16 | F36: 8 | G36: 1891
A37: IO Validation | B37: Validation | C37: Ang, Bense | D37: 6 | E37: 25 | F37: 6 | G37: 4074
A38: LSE - Mobile US | D38: 7 | E38: 22 | F38: 8 | G38: 4851
A39: Memory | B39: Validation | C39: Ang, Bense | D39: 14 | E39: 15 | F39: 21 | G39: 3638
A40: PCBCAD/COMP | B40: Platform Design | C40: Chen, Fairy | D40: 9 | E40: 41 | F40: 9 | G40: 3799
A41: Platform Design | B41: Platform Design | C41: Chen, Fairy | D41: 27 | E41: 38 | F41: 35 | G41: 12955
A42: Platform Design PM | B42: Platform Design | C42: Chen, Fairy | D42: 6 | E42: 33 | F42: 6 | G42: 2933
...

Sheet Raw
A1: Leader | B1: ORGLEVEL3 | C1: ORGLEVEL4 | D1: ORGLEVEL5 | E1: ORGLEVEL6 | F1: HC | G1: Potential Users | H1: Total Unique Active Users | I1: Total Active Users | J1: Participation Unique % | K1: Participation % | L1: Total Unlicensed Users | M1: Total AI LoC | N1: Total LoC | O1: Total % AI LoC
A2: Huynh, Jack | B2: McKeone, Tom | C2: Brinkley, Jeff | D2: Dong, Shirley | E2: Chen, Fairy | F2: 77 | G2: 71 | H2: 12 | I2: 14 | J2: 0.169 | K2: 0.197 | L2: 44 | M2: 28 | N2: 2075 | O2: 0.013
A3: Huynh, Jack | B3: McKeone, Tom | C3: Brinkley, Jeff | D3: Dong, Shirley | E3: Ang, Bense | F3: 102 | G3: 101 | H3: 18 | I3: 21 | J3: 0.178 | K3: 0.208 | L3: 74 | M3: 200 | N3: 542 | O3: 0.369
A4: Huynh, Jack | B4: McKeone, Tom | C4: Brinkley, Jeff | D4: Dong, Shirley | E4: Luo, Berlin | F4: 96 | G4: 95 | H4: 44 | I4: 45 | J4: 0.463 | K4: 0.474 | L4: 33 | M4: 206 | N4: 402 | O4: 0.512
A5: Huynh, Jack | B5: McKeone, Tom | C5: Brinkley, Jeff | D5: Dong, Shirley | E5: Yan, Frank | F5: 84 | G5: 83 | H5: 24 | I5: 26 | J5: 0.289 | K5: 0.313 | L5: 50 | M5: 0 | N5: 142 | O5: 0
A8: Leader | B8: ORGLEVEL3 | C8: ORGLEVEL4 | D8: ORGLEVEL5 | E8: ORGLEVEL6 | F8: HC | G8: Potential Users | H8: Total Unique Active Users | I8: Total Active Users | J8: Participation Unique % | K8: Participation % | L8: Total Unlicensed Users | M8: Total AI LoC | N8: Total LoC | O8: Total % AI LoC
A9: Huynh, Jack | B9: McKeone, Tom | C9: Brinkley, Jeff | D9: Dong, Shirley | E9: Chen, Fairy | F9: 77 | G9: 71 | H9: 12 | I9: 14 | J9: 0.169 | K9: 0.197 | L9: 44 | M9: 28 | N9: 2075 | O9: 0.013
A10: Huynh, Jack | B10: McKeone, Tom | C10: Brinkley, Jeff | D10: Dong, Shirley | E10: Ang, Bense | F10: 102 | G10: 101 | H10: 18 | I10: 21 | J10: 0.178 | K10: 0.208 | L10: 74 | M10: 200 | N10: 542 | O10: 0.369
A11: Huynh, Jack | B11: McKeone, Tom | C11: Brinkley, Jeff | D11: Dong, Shirley | E11: Luo, Berlin | F11: 96 | G11: 95 | H11: 44 | I11: 45 | J11: 0.463 | K11: 0.474 | L11: 33 | M11: 206 | N11: 402 | O11: 0.512
A12: Huynh, Jack | B12: McKeone, Tom | C12: Brinkley, Jeff | D12: Dong, Shirley | E12: Yan, Frank | F12: 84 | G12: 83 | H12: 24 | I12: 26 | J12: 0.289 | K12: 0.313 | L12: 50 | M12: 0 | N12: 142 | O12: 0
A13: Huynh, Jack | B13: McKeone, Tom | C13: Brinkley, Jeff | D13: Dong, Shirley | E13: (Blank) | F13: 1 | G13: (Blank) | H13: (Blank) | I13: (Blank) | J13: (Blank) | K13: (Blank) | L13: (Blank) | M13: (Blank) | N13: (Blank) | O13: 0
A14: Huynh, Jack | B14: McKeone, Tom | C14: Brinkley, Jeff | D14: Dong, Shirley | E14: Fang, James | F14: 38 | G14: 38 | H14: 12 | I14: 12 | J14: 0.316 | K14: 0.316 | L14: 16 | M14: (Blank) | N14: (Blank) | O14: 0
A15: Huynh, Jack | B15: McKeone, Tom | C15: Brinkley, Jeff | D15: Dong, Shirley | E15: Lu, Eagle | F15: 57 | G15: 56 | H15: 9 | I15: 9 | J15: 0.161 | K15: 0.161 | L15: 47 | M15: (Blank) | N15: (Blank) | O15: 0
A16: Huynh, Jack | B16: McKeone, Tom | C16: Brinkley, Jeff | D16: Dong, Shirley | E16: Lu, Hansen | F16: 15 | G16: 7 | H16: 1 | I16: 1 | J16: 0.143 | K16: 0.143 | L16: 4 | M16: (Blank) | N16: (Blank) | O16: 0
A17: Huynh, Jack | B17: McKeone, Tom | C17: Brinkley, Jeff | D17: Dong, Shirley | E17: Zhang, Jia | F17: 19 | G17: 17 | H17: 9 | I17: 9 | J17: 0.529 | K17: 0.529 | L17: 4 | M17: (Blank) | N17: (Blank) | O17: 0
A18: Huynh, Jack | B18: McKeone, Tom | C18: Brinkley, Jeff | D18: Dong, Shirley | E18: Zheng, Effie | F18: 97 | G18: 94 | H18: 9 | I18: 9 | J18: 0.096 | K18: 0.096 | L18: 77 | M18: (Blank) | N18: (Blank) | O18: 0
A19: Huynh, Jack | B19: McKeone, Tom | C19: Brinkley, Jeff | D19: Dong, Shirley | E19: Zhuang, Jeze | F19: 1 | G19: (Blank) | H19: (Blank) | I19: (Blank) | J19: (Blank) | K19: (Blank) | L19: (Blank) | M19: (Blank) | N19: (Blank) | O19: 0
